Workbook
Name FID_1: [1]AGR_Fuels!$A$2

Sheet EnergyBalance
P1: Default Units | Q1: Currency | R1: Activity | S1: Emissions
D2: COA | E2: GAS | F2: OIL | G2: NUC | H2: RNW | I2: SLU | J2: HET | K2: ELC | Q2: M€2005 | R2: PJ | S2: kt
D3: Solid Fuels | E3: Natural Gas | F3: Crude Oil | G3: Nuclear Energy | H3: Renewable Energies | I3: Industrial Wastes | J3: Derived Heat | K3: Electricity | L3: Total
C4: PRIMARY
B5: MIN | C5: Domestic Supply | D5: 8098.358 | E5: 7899.497 | F5: 5378.512 | G5: 10775.149 | H5: 5026.6 | I5: 0 | J5: 0 | K5: 0 | L5: =SUM(D5:K5) -> 37178.116
B6: IMP | C6: Imports | D6: 6462.671 | E6: 13291.729 | F6: 39959.98 | G6: 0 | H6: 113.019 | I6: 0.007 | J6: 0.153 | K6: 1167.52 | L6: =SUM(D6:K6) -> 60995.079
B7: EXP | C7: Exports | D7: -1147.069 | E7: -2516.331 | F7: -14830.662 | G7: 0 | H7: -72.404 | I7: 0 | J7: -0.129 | K7: -1126.804 | L7: =SUM(D7:K7) -> -19693.399
B8: TPS | C8: Total Primary Supply | D8: =SUM(D5:D7) -> 13413.96 | E8: =SUM(E5:E7) -> 18674.895 | F8: =SUM(F5:F7) -> 30507.83 | G8: =SUM(G5:G7) -> 10775.149 | H8: =SUM(H5:H7) -> 5067.215 | I8: =SUM(I5:I7) -> 0.007 | J8: =SUM(J5:J7) -> 0.024 | K8: =SUM(K5:K7) -> 40.716 | L8: =SUM(L5:L7) -> 78479.796
C9: CONVERSION
B10: ESC | C10: Energy Sector Consumption | D10: -57.638 | E10: -792.98 | F10: -1848.605 | G10: 0 | H10: -4.283 | I10: -1.52 | J10: 0 | K10: 0 | L10: =SUM(D10:K10) -> -2705.026
B11: ELC | C11: Electricity Plants | D11: -9598.12 | E11: -5635.544 | F11: -1224.609 | G11: -10775.149 | H11: -1255.692 | I11: -32.949 | J11: 1737.559 | K11: 11581 | L11: =SUM(D11:K11) -> -15203.504
B12: HPL | C12: Heat Plants | D12: -161.396 | E12: -301.301 | F12: -49.649 | G12: 0 | H12: -140.207 | I12: -1.569 | J12: 658.743 | K12: 0 | L12: =SUM(D12:K12) -> 4.621
B13: REF | C13: Petroleum Refineries | F13: -31736.461 | L13: =SUM(D13:K13) -> -31736.461
C14: Total Conversion | D14: =SUM(D10:D13) -> -9817.154 | E14: =SUM(E10:E13) -> -6729.825 | F14: =SUM(F10:F13) -> -34859.324 | G14: =SUM(G10:G13) -> -10775.149 | H14: =SUM(H10:H13) -> -1400.182 | I14: =SUM(I10:I13) -> -36.038 | J14: =SUM(J10:J13) -> 2396.302 | K14: =SUM(K10:K13) -> 11581 | L14: =SUM(L10:L13) -> -49640.37
C15: FINAL
B16: RSD | C16: Residential | D16: 356.555 | E16: 5159.793 | F16: 2289.293 | G16: 0 | H16: 1293.927 | I16: 0 | J16: 865.485 | K16: 2871.742 | L16: =SUM(D16:K16) -> 12836.795
B17: COM | C17: Commercial | D17: 56.925 | E17: 1751.73 | F17: 854.81 | G17: 0 | H17: 67.406 | I17: 1.217 | J17: 254.646 | K17: 2527.391 | L17: =SUM(D17:K17) -> 5514.125
B18: IND | C18: Industry | D18: 1896.986 | E18: 4437.161 | F18: 2016.111 | G18: 0 | H18: 721.671 | I18: 117.192 | J18: 633.583 | K18: 4088.444 | L18: =SUM(D18:K18) -> 13911.148
B19: AGR | C19: Agriculture | D19: 44.1 | E19: 201.206 | F19: 797.372 | G19: 0 | H19: 63.086 | I19: 0.001 | J19: 15.574 | K19: 19.386 | L19: =SUM(D19:K19) -> 1140.725
B20: TRA | C20: Transport | D20: 0.556 | E20: 21.249 | F20: 14851.249 | G20: 0 | H20: 130.685 | I20: 0 | J20: 0 | K20: 265.972 | L20: =SUM(D20:K20) -> 15269.711
B21: OTH | C21: Other | D21: =IF((SUM(D16:D20,D22:D23)-SUM(D10:D12))>D8,0,(D8-SUM(D16:D20,D22:D23)+SUM(D10:D12))) -> 1189.231 | E21: =IF((SUM(E16:E20,E22:E23)-SUM(E10:E12))>E8,0,(E8-SUM(E16:E20,E22:E23)+SUM(E10:E12))) -> 0 | F21: 392.532 | G21: =IF((SUM(G16:G20,G22:G23)-SUM(G10:G12))>G8,0,(G8-SUM(G16:G20,G22:G23)+SUM(G10:G12))) -> 0 | H21: =IF((SUM(H16:H20,H22:H23)-SUM(H10:H12))>H8,0,(H8-SUM(H16:H20,H22:H23)+SUM(H10:H12))) -> 1390.258 | I21: =IF((SUM(I16:I20,I22:I23)-SUM(I10:I12))>I8,0,(I8-SUM(I16:I20,I22:I23)+SUM(I10:I12))) -> 0 | J21: =IF((SUM(J16:J20,J22:J23)-SUM(J10:J12))>J8,0,(J8-SUM(J16:J20,J22:J23)+SUM(J10:J12))) -> 627.038 | K21: 650 | L21: =SUM(D21:K21) -> 4249.059
B22: NEN | C22: Non Energy | D22: 52.453 | E22: 633.823 | F22: 4072.508 | H22: 0 | I22: 0 | J22: 0 | K22: 0 | L22: =SUM(D22:K22) -> 4758.784
B23: BNK | C23: Bunkers | D23: 0 | E23: 0 | F23: 2111.092 | H23: 0 | I23: 0 | J23: 0 | K23: 0 | L23: =SUM(D23:K23) -> 2111.092
B24: TFC | C24: Total Final Consumption | D24: =SUM(D16:D23) -> 3596.806 | E24: =SUM(E16:E23) -> 12204.962 | F24: =SUM(F16:F23) -> 27384.967 | G24: =SUM(G16:G23) -> 0 | H24: =SUM(H16:H23) -> 3667.033 | I24: =SUM(I16:I23) -> 118.41 | J24: =SUM(J16:J23) -> 2396.326 | K24: =SUM(K16:K23) -> 10422.935 | L24: =SUM(L16:L23) -> 59791.439
C27: Data used in the template to buld the model
D36: COA
C37: Domestic Supply Curve Share - Step 1 | D37: 0.75
C38: Domestic Supply Curve Share - Step 2 | D38: 0.25

Sheet RES&OBJ
B2: Objective Function | K2: Objective Function by Scenario
K3: _SysCost VEDA-BE table
B4: Run name: DemoS_001
B14: Reference Energy System (from VEDA-FE Go-To RES feature)
D16: Primary Supply (Mining, Import/Export and total primary supply demand)

Sheet DemTechs_TPS
B1: Sector Name | C1: Description | D1: Type | E1: Default Unit | F1: Currency Unit | H1: Existing
B2: =EnergyBalance!B8 -> TPS | C2: =EnergyBalance!C8 -> Total Primary Supply | D2: ="Demand Technology" -> Demand Technology | E2: =EnergyBalance!R2 -> PJ | F2: =EnergyBalance!Q2 -> M€2005 | H2: E | N2: ~FI_Comm | X2: ~FI_Process
N3: Csets | O3: Region | P3: CommName | Q3: CommDesc | R3: Unit | S3: LimType | T3: PeakTS | U3: Ctype | X3: Sets | Y3: Region | Z3: TechName | AA3: TechDesc | AB3: Tact | AC3: Tcap | AD3: PrimaryCG
N4: *Commodity Set Membership | O4: Region Name | P4: Commodity Name | Q4: Commodity Description | R4: Unit | S4: Sense of the Balance EQN. | T4: Peak Monitoring | U4: Wskaźnik energii elektrycznej | X4: *Process Set Membership | Y4: Region Name | Z4: Technology Name | AA4: Technology Description | AB4: Activity Unit | AC4: Capacity Unit | AD4: Primary Commodity Group
N5: NRG | O5: PL | P5: PRI_BIOG_AGR | Q5: Biogas AGR | R5: PJ | X5: *
N6: NRG | O6: PL | P6: PRI_BIO_CH4_AGR | Q6: Biometan AGR | R6: PJ | X6: DMD | Y6: PL | Z6: AGR_DEM_AGR | AA6: Agriculture Demand Process | AB6: IPI | AC6: IPIa
N7: DEM | O7: PL | P7: AGR_DEM | Q7: Agriculture Demand | R7: IPI | X7: PRE | Y7: PL | Z7: AGR_EX_BIOG | AA7: Agriculture Existing Biogass | AB7: PJ | AC7: mln m3
D8: ~FI_T | N8: NRG | O8: PL | P8: AGR_LIV_MANURE_CAT_DAIRY | Q8: Animal Manure - Dairy Cattle | R8: kt | X8: PRE | Y8: PL | Z8: AGR_EX_BIOG_CLEAN | AA8: Agriculture Biogaz Cleaning | AB8: PJ | AC8: Pja
B9: TechName | C9: * TechDesc | D9: Comm-IN | E9: Comm-OUT | F9: STOCK | G9: Input | H9: OUTPUT | I9: Cap2Act | J9: AFA | N9: NRG | O9: PL | P9: AGR_LIV_MANURE_CAT_NON-DAIRY | Q9: Animal Manure - Non Dairy Cattle | R9: kt | X9: IMP | Y9: PL | Z9: AGR_IMP_DUMMY_FOOD_LIV | AA9: Dummy Energy Import | AB9: IPI | AC9: 1000s of animals
B10: *Technology Name | C10: Technology description | D10: Input Commodity | E10: Output Commodity | F10: Existing Installed Capacity | G10: Fuel Input per 1000 Animals | H10: kt/1000 animals | I10: Animals per year | N10: NRG | O10: PL | P10: AGR_LIV_MANURE_SWINE | Q10: Animal Manure - Swine | R10: kt | X10: IMP | Y10: PL | Z10: AGR_IMP_DUMMY_LAND | AA10: Dummy Land Import | AB10: kha/a | AC10: kha
B11: *Units | C11: *Units | F11: Thousands Animals | I11: €/kWel | J11: €/(kW×a) | N11: NRG | O11: PL | P11: AGR_LIV_MANURE_POULTRY | Q11: Animal Manure - Poultry | R11: kt | X11: PRE | Y11: PL | Z11: AGR_EX_LIV_CAT_DAIRY | AA11: AGR_LIV_CAT_DAIRY | AB11: IPI | AC11: 1000s of animals
B12: AGR_EX_LIV_CAT_DAIRY | C12: AGR_LIV_CAT_DAIRY | F12: 2391.308 | I12: 1 | J12: 1 | N12: NRG | O12: PL | P12: AGR_RESID_CROP_WHEAT | Q12: Crop Residues | R12: kt | X12: PRE | Y12: PL | Z12: AGR_EX_LIV_CAT_NON-DAIRY | AA12: AGR_LIV_CAT_NON-DAIRY | AB12: IPI | AC12: 1000s of animals
D13: AGR_LIVESTOCK_FOOD | G13: 1 | N13: NRG | O13: PL | P13: AGR_RESID_CROP_BARLEY | Q13: Crop Residues | R13: kt | X13: PRE | Y13: PL | Z13: AGR_EX_LIV_SWINE | AA13: AGR_LIV_SWINE | AB13: IPI | AC13: 1000s of animals
E14: AGR_DEM_LIV_CAT_DAIRY | N14: NRG | O14: PL | P14: AGR_RESID_CROP_MAIZE | Q14: Crop Residues | R14: kt | X14: PRE | Y14: PL | Z14: AGR_EX_LIV_POULTRY | AA14: AGR_LIV_POULTRY | AB14: IPI | AC14: 1000s of animals
E15: AGR_LIV_MANURE_CAT_DAIRY | H15: 7.4 | N15: NRG | O15: PL | P15: AGR_RESID_CROP_CER-MIX | Q15: Crop Residues | R15: kt | X15: PRE | Y15: PL | Z15: AGR_EX_LIV_INDIRECT | AA15: AGR_EX_LIV_INDIRECT | AB15: IPI | AC15: 1000s of animals
B16: AGR_EX_LIV_CAT_NON-DAIRY | C16: AGR_LIV_CAT_NON-DAIRY | F16: 3887.588 | I16: 1 | J16: 1 | N16: NRG | O16: PL | P16: AGR_RESID_CROP_TRITICALE | Q16: Crop Residues | R16: kt | X16: PRE | Y16: PL | Z16: AGR_LAND_CROP_WHEAT | AA16: AGR_LAND_CROP_WHEAT | AB16: kt | AC16: kt
D17: AGR_LIVESTOCK_FOOD | G17: 1 | N17: NRG | O17: PL | P17: AGR_RESID_CROP_OATS | Q17: Crop Residues | R17: kt | X17: PRE | Y17: PL | Z17: AGR_LAND_CROP_BARLEY | AA17: AGR_LAND_CROP_BARLEY | AB17: kt | AC17: kt
E18: AGR_DEM_LIV_CAT_NON-DAIRY | N18: NRG | O18: PL | P18: AGR_RESID_CROP_RYE | Q18: Crop Residues | R18: kt | X18: PRE | Y18: PL | Z18: AGR_LAND_CROP_MAIZE | AA18: AGR_LAND_CROP_MAIZE | AB18: kt | AC18: kt
E19: AGR_LIV_MANURE_CAT_NON-DAIRY | H19: 2.928 | N19: NRG | O19: PL | P19: AGR_RESID_CROP_MILL-BUCK | Q19: Crop Residues | R19: kt | X19: PRE | Y19: PL | Z19: AGR_LAND_CROP_CER-MIX | AA19: AGR_LAND_CROP_CER-MIX | AB19: kt | AC19: kt
B20: AGR_EX_LIV_SWINE | C20: AGR_LIV_SWINE | F20: 11727.41 | I20: 1 | J20: 1 | N20: MAT | O20: PL | P20: AGR_LIVESTOCK_FOOD | Q20: Dummy Energy for Agriculture | R20: DUM | X20: PRE | Y20: PL | Z20: AGR_LAND_CROP_TRITICALE | AA20: AGR_LAND_CROP_TRITICALE | AB20: kt | AC20: kt
D21: AGR_LIVESTOCK_FOOD | G21: 1 | N21: MAT | O21: PL | P21: AGR_LAND | Q21: Dummy Energy for Agriculture | R21: kha | X21: PRE | Y21: PL | Z21: AGR_LAND_CROP_OATS | AA21: AGR_LAND_CROP_OATS | AB21: kt | AC21: kt
E22: AGR_DEM_LIV_SWINE | N22: NRG | O22: PL | P22: AGR_DUMMY_DMD_LAND | Q22: Dummy Land Demand for Agriculture | R22: DUM | X22: PRE | Y22: PL | Z22: AGR_LAND_CROP_RYE | AA22: AGR_LAND_CROP_RYE | AB22: kt | AC22: kt
E23: AGR_LIV_MANURE_SWINE | H23: 0.675 | N23: NRG | O23: PL | P23: AGR_DUMMY_LAND_RESIDUES | Q23: Dummy Crop Residues for Biogas Production | R23: DUM | X23: PRE | Y23: PL | Z23: AGR_LAND_CROP_MILL-BUCK | AA23: AGR_LAND_CROP_MILL-BUCK | AB23: kt | AC23: kt
B24: AGR_EX_LIV_POULTRY | C24: AGR_LIV_POULTRY | F24: 205774.51 | I24: 1 | J24: 1 | N24: DEM | O24: PL | P24: AGR_DEM_LIV_CAT_DAIRY | Q24: AGR_DEM_LIV_CAT_DAIRY | R24: kt
D25: AGR_LIVESTOCK_FOOD | G25: 1 | N25: DEM | O25: PL | P25: AGR_DEM_LIV_CAT_NON-DAIRY | Q25: AGR_DEM_LIV_CAT_NON-DAIRY | R25: kt
E26: AGR_DEM_LIV_POULTRY | N26: DEM | O26: PL | P26: AGR_DEM_LIV_SWINE | Q26: AGR_DEM_LIV_SWINE | R26: kt
E27: AGR_LIV_MANURE_POULTRY | H27: 0.01125 | N27: DEM | O27: PL | P27: AGR_DEM_LIV_POULTRY | Q27: AGR_DEM_LIV_POULTRY | R27: kt
N28: DEM | O28: PL | P28: AGR_DEM_CROP_WHEAT | Q28: Crop Residues | R28: kt
N29: DEM | O29: PL | P29: AGR_DEM_CROP_BARLEY | Q29: Crop Residues | R29: kt
N30: DEM | O30: PL | P30: AGR_DEM_CROP_MAIZE | Q30: Crop Residues | R30: kt
D31: ~FI_T | N31: DEM | O31: PL | P31: AGR_DEM_CROP_CER-MIX | Q31: Crop Residues | R31: kt
B32: TechName | C32: * TechDesc | D32: Comm-IN | E32: Comm-OUT | F32: STOCK | G32: Input | H32: OUTPUT | I32: Cap2Act | J32: ACTFLO | K32: AFA | N32: DEM | O32: PL | P32: AGR_DEM_CROP_TRITICALE | Q32: Crop Residues | R32: kt
B33: *Technology Name | C33: Technology description | D33: Input Commodity | E33: Output Commodity | F33: Existing Installed Capacity | G33: Fuel Input per 1000 Animals | H33: kt/1000 animals | N33: DEM | O33: PL | P33: AGR_DEM_CROP_OATS | Q33: Crop Residues | R33: kt
B34: *Units | C34: *Units | F34: k ha | G34: kha/kha | H34: kt/kha | J34: kt/kha | N34: DEM | O34: PL | P34: AGR_DEM_CROP_RYE | Q34: Crop Residues | R34: kt
B35: AGR_LAND_CROP_WHEAT | C35: AGR_LAND_CROP_WHEAT | F35: 2373.3 | I35: 1 | K35: 1 | N35: DEM | O35: PL | P35: AGR_DEM_CROP_MILL-BUCK | Q35: Crop Residues | R35: kt
D36: AGR_LAND | G36: 1
E37: AGR_DEM_CROP_WHEAT | J37: 5.34
E38: AGR_RESID_CROP_WHEAT | H38: 0.78389961
B39: AGR_LAND_CROP_BARLEY | C39: AGR_LAND_CROP_BARLEY | F39: 675.3 | I39: 1 | K39: 1
D40: AGR_LAND | G40: 1
...

Sheet SUP
B1: Sector Name | C1: Commodity | D1: Description | E1: Default Unit | G1: Currency Unit
C2: =EnergyBalance!D2 -> COA | D2: =EnergyBalance!D3 -> Solid Fuels | E2: =EnergyBalance!R2 -> PJ | G2: =EnergyBalance!Q2 -> M€2005
D7: ~FI_T
B8: TechName | C8: *TechDesc | D8: Comm-OUT | E8: COST
B9: *Technology Name | C9: Technology description | D9: Output Commodity | E9: Cost
B10: *Units | C10: *Units | E10: =$G$2&"/"&$E$2 -> M€2005/PJ
B11: AGR_IMP_DUMMY_FOOD_LIV | C11: Dummy Energy Import | D11: AGR_LIVESTOCK_FOOD | E11: 0.001
B12: AGR_IMP_DUMMY_LAND | C12: Dummy Land Import | D12: AGR_LAND | E12: 0.001

Sheet Demands
B1: Sector Name | C1: Commodity | D1: Description | E1: Default Unit | G1: Currency Unit
B2: DEM | E2: =EnergyBalance!R2 -> PJ | G2: =EnergyBalance!Q2 -> M€2005
C5: ~FI_T
B6: Attribute | C6: CommName | D6: *Unit | E6: 2005
B7: * | C7: Demand Commodity Name | D7: Demand Unit | E7: Demand Value
B8: *Units | E8: =E2 -> PJ
B9: Demand | C9: =DemTechs_TPS!P5 -> PRI_BIOG_AGR | D9: PJ | E9: 1
B10: Demand | C10: =DemTechs_TPS!P6 -> PRI_BIO_CH4_AGR | D10: PJ | E10: 1
